Workbook

Sheet Pivot Table 5
A1: Archived User Email | B1: New Owner Email | C1: Status | D1: Details | E1: Last Updated
A2: =IFERROR(__xludf.DUMMYFUNCTION("{""Department 🔂""; ARRAYFORMULA( IFERROR( FILTER(UNIQUE('On-Boarding'!$D$2:$D1002), UNIQUE('On-Boarding'!$D$2:$D1002) <> """") , """") ); ""Grand Total""}"),"Department 🔂") -> Department 🔂 | B2: Active Accounts 🔂
A3: =IFERROR(__xludf.DUMMYFUNCTION("""COMPUTED_VALUE"""),"Strategy") -> Strategy | B3: =(IF(A2:A1002 = "", "", COUNTIFS('On-Boarding'!$D$2:$D1002, A2:A1002, 'On-Boarding'!$L$2:$L1002, ""))) -> 14 | D3: 7+HOD
A4: =IFERROR(__xludf.DUMMYFUNCTION("""COMPUTED_VALUE"""),"Legal") -> Legal | B4: =(IF(A3:A1002 = "", "", COUNTIFS('On-Boarding'!$D$2:$D1002, A3:A1002, 'On-Boarding'!$L$2:$L1002, ""))) -> 8 | D4: 7+HOD
A5: =IFERROR(__xludf.DUMMYFUNCTION("""COMPUTED_VALUE"""),"Org") -> Org | B5: =(IF(A4:A1002 = "", "", COUNTIFS('On-Boarding'!$D$2:$D1002, A4:A1002, 'On-Boarding'!$L$2:$L1002, ""))) -> 13 | D5: 7
A6: =IFERROR(__xludf.DUMMYFUNCTION("""COMPUTED_VALUE"""),"Brand Marketing") -> Brand Marketing | B6: =(IF(A5:A1002 = "", "", COUNTIFS('On-Boarding'!$D$2:$D1002, A5:A1002, 'On-Boarding'!$L$2:$L1002, ""))) -> 19 | D6: 7+HOD
A7: =IFERROR(__xludf.DUMMYFUNCTION("""COMPUTED_VALUE"""),"Technology") -> Technology | B7: =(IF(A6:A1002 = "", "", COUNTIFS('On-Boarding'!$D$2:$D1002, A6:A1002, 'On-Boarding'!$L$2:$L1002, ""))) -> 69 | D7: 7+HOD
A8: =IFERROR(__xludf.DUMMYFUNCTION("""COMPUTED_VALUE"""),"Digital Marketing") -> Digital Marketing | B8: =(IF(A7:A1002 = "", "", COUNTIFS('On-Boarding'!$D$2:$D1002, A7:A1002, 'On-Boarding'!$L$2:$L1002, ""))) -> 18 | D8: 7+HOD
A9: =IFERROR(__xludf.DUMMYFUNCTION("""COMPUTED_VALUE"""),"Customer Experience") -> Customer Experience | B9: =(IF(A8:A1002 = "", "", COUNTIFS('On-Boarding'!$D$2:$D1002, A8:A1002, 'On-Boarding'!$L$2:$L1002, ""))) -> 31 | D9: 7+HOD
A10: =IFERROR(__xludf.DUMMYFUNCTION("""COMPUTED_VALUE"""),"Data") -> Data | B10: =(IF(A9:A1002 = "", "", COUNTIFS('On-Boarding'!$D$2:$D1002, A9:A1002, 'On-Boarding'!$L$2:$L1002, ""))) -> 32 | D10: 7+HOD
A11: =IFERROR(__xludf.DUMMYFUNCTION("""COMPUTED_VALUE"""),"Human Resources") -> Human Resources | B11: =(IF(A10:A1002 = "", "", COUNTIFS('On-Boarding'!$D$2:$D1002, A10:A1002, 'On-Boarding'!$L$2:$L1002, ""))) -> 16 | D11: 7+HOD
A12: =IFERROR(__xludf.DUMMYFUNCTION("""COMPUTED_VALUE"""),"Product Design") -> Product Design | B12: =(IF(A11:A1002 = "", "", COUNTIFS('On-Boarding'!$D$2:$D1002, A11:A1002, 'On-Boarding'!$L$2:$L1002, ""))) -> 8 | D12: 7+HOD
A13: =IFERROR(__xludf.DUMMYFUNCTION("""COMPUTED_VALUE"""),"Finance") -> Finance | B13: =(IF(A12:A1002 = "", "", COUNTIFS('On-Boarding'!$D$2:$D1002, A12:A1002, 'On-Boarding'!$L$2:$L1002, ""))) -> 23 | D13: 7+HOD
A14: =IFERROR(__xludf.DUMMYFUNCTION("""COMPUTED_VALUE"""),"Product") -> Product | B14: =(IF(A13:A1002 = "", "", COUNTIFS('On-Boarding'!$D$2:$D1002, A13:A1002, 'On-Boarding'!$L$2:$L1002, ""))) -> 24 | D14: 7+HOD
A15: =IFERROR(__xludf.DUMMYFUNCTION("""COMPUTED_VALUE"""),"IT Infra") -> IT Infra | B15: =(IF(A14:A1002 = "", "", COUNTIFS('On-Boarding'!$D$2:$D1002, A14:A1002, 'On-Boarding'!$L$2:$L1002, ""))) -> 12 | D15: 7+HOD
A16: =IFERROR(__xludf.DUMMYFUNCTION("""COMPUTED_VALUE"""),"P R & Corporate Comms") -> P R & Corporate Comms | B16: =(IF(A15:A1002 = "", "", COUNTIFS('On-Boarding'!$D$2:$D1002, A15:A1002, 'On-Boarding'!$L$2:$L1002, ""))) -> 2 | D16: 7+HOD
A17: =IFERROR(__xludf.DUMMYFUNCTION("""COMPUTED_VALUE"""),"Public Policy") -> Public Policy | B17: =(IF(A16:A1002 = "", "", COUNTIFS('On-Boarding'!$D$2:$D1002, A16:A1002, 'On-Boarding'!$L$2:$L1002, ""))) -> 1 | D17: 7+HOD
A18: =IFERROR(__xludf.DUMMYFUNCTION("""COMPUTED_VALUE"""),"Founder's Office") -> Founder's Office | B18: =(IF(A17:A1002 = "", "", COUNTIFS('On-Boarding'!$D$2:$D1002, A17:A1002, 'On-Boarding'!$L$2:$L1002, ""))) -> 5 | D18: 7+HOD
A19: =IFERROR(__xludf.DUMMYFUNCTION("""COMPUTED_VALUE"""),"Administration") -> Administration | B19: =(IF(A18:A1002 = "", "", COUNTIFS('On-Boarding'!$D$2:$D1002, A18:A1002, 'On-Boarding'!$L$2:$L1002, ""))) -> 3 | D19: 7+HOD
A20: =IFERROR(__xludf.DUMMYFUNCTION("""COMPUTED_VALUE"""),"strategy") -> strategy | B20: =(IF(A19:A1002 = "", "", COUNTIFS('On-Boarding'!$D$2:$D1002, A19:A1002, 'On-Boarding'!$L$2:$L1002, ""))) -> 14 | D20: 7+HOD
A21: =IFERROR(__xludf.DUMMYFUNCTION("""COMPUTED_VALUE"""),"Vertical Tv") -> Vertical Tv | B21: =(IF(A20:A1002 = "", "", COUNTIFS('On-Boarding'!$D$2:$D1002, A20:A1002, 'On-Boarding'!$L$2:$L1002, ""))) -> 86 | D21: 7+HOD
A22: =IFERROR(__xludf.DUMMYFUNCTION("""COMPUTED_VALUE"""),"Nucanon") -> Nucanon | B22: =(IF(A21:A1002 = "", "", COUNTIFS('On-Boarding'!$D$2:$D1002, A21:A1002, 'On-Boarding'!$L$2:$L1002, ""))) -> 1 | D22: 7+HOD
A23: =IFERROR(__xludf.DUMMYFUNCTION("""COMPUTED_VALUE"""),"Grand Total") -> Grand Total | B23: =SUM(B4:B22) -> 385
A26: User Group_JumpCloud | B26: User Group ID_GWS | D26: New OU Recommendation | E26: Status
A27: Org | B27: jcorg@zupee.in | D27: Administration | E27: x
A28: Technology | B28: jctech@zupee.in | D28: Brand Marketing | E28: x
A29: Product Design | B29: jcproduct@zupee.in | D29: C-Suite | E29: x
A30: Administration | B30: jcadm@zupee.in | D30: Customer Experience | E30: x
A31: Data | B31: jcdata@zupee.in | D31: Chromebook VIP and Ticketing Team | E31: x
A32: Human Resources | B32: jchr@zupee.in | D32: ChromeBook OB Team | E32: x
A33: Strategy | B33: jcst@zupee.in | D33: Data | E33: x
A34: Digital Marketing | B34: jcdm@zupee.in | D34: Digital Marketing | E34: x
A35: Brand Marketing | B35: jcbm@zupee.in | D35: Finance | E35: x
A36: Finance | B36: jcfinance@zupee.in | D36: Founder's Office | E36: x
A37: IT Infra | B37: jcitinfra@zupee.in | D37: Head Of Department | E37: x
... A44: Vertical TV | B44: jc.vtv@zupee.in | D44: Public Policy | E44: x
A45: Nucanon | D45: Strategy | E45: x
D46: Technology | E46: x
D47: Vertical TV | E47: x
D48: Generic ID | E48: x
...

Sheet On-Boarding
A1: Creation Date | B1: Full Name | C1: Office Email Address | D1: Department | E1: Acc Info | F1: Work Phone | G1: Employee Type | H1: Employee Title [Required] | I1: Manager Email [Required] | J1: Personal Email ID | K1: Remarks (If any) | L1: {={"No-Dues St"; IF(ISNA(VLOOKUP(C2:C1542, 'Off-Boarding'!B:B, 1, FALSE)), "", "No-Dues")}} -> No-Dues St
A2: 01-Jan-1111 | B2: Rohan Ray | C2: rohan.ray@zupee.in | D2: Strategy | E2: GWS | F2: 7022967608 | G2: Full Time | H2: Content Operations Associate | I2: chirag.sabhadiya@zupee.in | L2: No-Dues
A3: 01-Jan-1111 | B3: Aakash Pal | C3: aakash.pal@zupee.in | E3: GWS
A4: 01-Jan-1111 | B4: Aatmiy Tomar | C4: aatmiy.tomar@zupee.in | E4: GWS
A5: 01-Jan-1111 | B5: Aayushi Siddhi Bhatta | C5: aayushi.bhatta@zupee.in | E5: GWS
A6: 01-Jan-1111 | B6: Aayushi Sharma | C6: aayushi.sharma@zupee.in | E6: GWS
A7: 01-Jan-1111 | B7: Abhinav Magow | C7: abhinav.magow@zupee.in | E7: GWS
A8: 01-Jan-1111 | B8: Abhinav Srivastava | C8: abhinav.srivastava@zupee.in | E8: GWS
A9: 01-Jan-1111 | B9: Abhinav Venkat | C9: abhinav.venkat@zupee.in | E9: GWS
A10: 01-Jan-1111 | B10: Abhishek Aga | C10: abhishek.aga@zupee.in | E10: GWS
A11: 01-Jan-1111 | B11: Abhishek Anand | C11: abhishek.anand@zupee.in | E11: GWS
A12: 01-Jan-1111 | B12: Abhishek Chaudhary | C12: abhishek.chaudhary@zupee.in | E12: GWS
A13: 01-Jan-1111 | B13: Abhishek Kumar | C13: abhishek.kumar@zupee.in | E13: GWS
A14: 01-Jan-1111 | B14: Abhishek Maheshwari | C14: abhishek.maheshwari@zupee.in | E14: GWS
... A17: 01-Jan-1111 | B17: Abhishek Raj | C17: abhishek.raj@zupee.in | E17: GWS
A18: 01-Jan-1111 | B18: Abhishek Singh | C18: abhishek.singh@zupee.in | E18: GWS | L18: No-Dues
A19: 01-Jan-1111 | B19: Achla Vatsa | C19: achla.vatsa@zupee.in | E19: GWS
A20: 01-Jan-1111 | B20: Adesh Sharma | C20: adesh.sharma@zupee.in | E20: GWS | L20: No-Dues
A21: 01-Jan-1111 | B21: Aditya Ganguly | C21: aditya.ganguly@zupee.in | E21: GWS
A22: 01-Jan-1111 | B22: Aditya Garg | C22: aditya.garg@zupee.in | E22: GWS | L22: No-Dues
A23: 01-Jan-1111 | B23: Aditya Marda | C23: aditya.marda@zupee.in | E23: GWS | L23: No-Dues
A24: 01-Jan-1111 | B24: Advait Mulay - Intern | C24: advait.mulay@zupee.in | E24: GWS
A25: 01-Jan-1111 | B25: Afshan Akram | C25: afshan.akram@zupee.in | E25: GWS
A26: 01-Jan-1111 | B26: Ajayraj Singh - Intern | C26: ajayraj.singh@zupee.in | E26: GWS
A27: 01-Jan-1111 | B27: Ajinkya Sirohi | C27: ajinkya.sirohi@zupee.in | E27: GWS
A28: 01-Jan-1111 | B28: Ajitesh Mohanta | C28: ajitesh.mohanta@zupee.in | E28: GWS
A29: 01-Jan-1111 | B29: Akanksha Bhatia | C29: akanksha.bhatia@zupee.in | E29: GWS
A30: 01-Jan-1111 | B30: Akash Bisht | C30: akash.bisht@zupee.in | E30: GWS | L30: No-Dues
A31: 01-Jan-1111 | B31: Akash Chauhan | C31: akash.chauhan@zupee.in | E31: GWS
A32: 01-Jan-1111 | B32: Akhilesh Boppana | C32: akhilesh.boppana@zupee.in | E32: GWS
A33: 01-Jan-1111 | B33: Akshay Kumar | C33: akshay.kumar@zupee.in | E33: GWS
A34: 01-Jan-1111 | B34: Akshit Kumar | C34: akshit.kumar@zupee.in | E34: GWS | L34: No-Dues
A35: 01-Jan-1111 | B35: Aksshay Malaviya | C35: aksshay.malaviya@zupee.in | E35: GWS
A36: 01-Jan-1111 | B36: Alankrita Sharma | C36: alankrita.sharma@zupee.in | E36: GWS | L36: No-Dues
A37: 01-Jan-1111 | B37: Alok | C37: alok.mahor@zupee.in | E37: GWS
A38: 01-Jan-1111 | B38: Alok Singh | C38: alok.singh@zupee.in | E38: GWS
A39: 01-Jan-1111 | B39: Alpika Singh | C39: alpika.singh@zupee.in | E39: GWS | L39: No-Dues
A40: 01-Jan-1111 | B40: Aman Choudhury | C40: aman.choudhury@zupee.in | E40: GWS
A41: 01-Jan-1111 | B41: Aman Ludhwani | C41: aman.ludhwani@zupee.in | E41: GWS | L41: No-Dues
A42: 01-Jan-1111 | B42: Amit Arora | C42: amit.arora@zupee.in | E42: GWS
...

Sheet Off-Boarding
A1: Accounts Info | C1: Last Working Info | E1: Users Access Info
A2: Full Name | B2: Email ID | C2: IT LWD Date | D2: Frm Keka LWD | E2: IT GWS St | F2: {={" Department"; IF(ISNA(VLOOKUP(B3:B829, 'On-Boarding'!C2:D829, 2, FALSE)), "", VLOOKUP(B3:B829, 'On-Boarding'!C2:D829, 2, FALSE))}} -> #REF! | G2: Acc & Mail's St | H2: GWS Status Details | I2: Slack | J2: O365 | K2: Jira | L2: New Rlc | M2: Adobe | N2: Bitbkt | O2: CRM DB | P2: Mtrx DB | Q2: Clvr Tap | R2: Assets | S2: Remarks | T2: {={"Days Overdue"; IF(C3:C829="", "", IF(TODAY() - C3:C829 > 30, "> 30 Days", "≤ 30 Days"))}} -> Days Overdue
A3: {=IFERROR(VLOOKUP(B3,{Lists!$H$4:$H829,Lists!$G$4:$G829},2,0),"")} -> Aditya Pawar | B3: aditya.pawar@zupee.in | C3: 1-Jan-1111 | D3: 1-Jan-1111 | E3: Suspend | G3: NOT_FOUND | H3: Mail does not exist in GWS | I3: ❌ | J3: ❌ | K3: ❌ | L3: ❌ | M3: ❌ | N3: ❌ | O3: ❌ | P3: ❌ | Q3: ❌ | T3: > 30 Days
A4: {=IFERROR(VLOOKUP(B4,{Lists!$H$4:$H829,Lists!$G$4:$G829},2,0),"")} -> Rohit Chhabra | B4: rohit.chhabra@zupee.in | C4: 1-Jan-1111 | D4: 1-Jan-1111 | E4: =VLOOKUP(B4,AT_Data!A:D,4,0) -> Revoked | G4: NOT_FOUND | H4: Mail does not exist in GWS | I4: ❌ | J4: ❌ | K4: ❌ | L4: ❌ | M4: ❌ | N4: ❌ | O4: ❌ | P4: ❌ | Q4: ❌ | S4: using By Hitesh Vats, appv by Raj on Slack | T4: > 30 Days
A5: Shristi Agrawal | B5: shristi.agrawal@zupee.in | C5: 45392 | E5: Suspend | G5: NOT_FOUND | H5: Mail does not exist in GWS | I5: ✅ | J5: ❌ | K5: ✅ | L5: ✅ | M5: ❌ | N5: ❌ | O5: ✅ | P5: ✅ | Q5: ✅ | T5: > 30 Days
A6: Abhishek Singh | B6: abhishek.singh@zupee.in | C6: 45393 | E6: Suspend | G6: NOT_FOUND | H6: Mail does not exist in GWS | I6: ✅ | J6: ✅ | K6: ❌ | L6: ❌ | M6: ❌ | N6: ❌ | O6: ✅ | P6: ❌ | Q6: ❌ | T6: > 30 Days
A7: Khushboo kushwah | B7: khushboo.kushwah@zupee.in | C7: 45394 | E7: Suspend | G7: NOT_FOUND | H7: Mail does not exist in GWS | I7: ❌ | J7: ❌ | K7: ❌ | L7: ❌ | M7: ❌ | N7: ❌ | O7: ✅ | P7: ✅ | Q7: ❌ | T7: > 30 Days
A8: Divya Wangoo | B8: divya.wangoo@zupee.in | C8: 45455 | E8: Suspend | G8: NOT_FOUND | H8: Mail does not exist in GWS | I8: ✅ | J8: ❌ | K8: ✅ | L8: ✅ | M8: ❌ | N8: ❌ | O8: ✅ | P8: ✅ | Q8: ✅ | T8: > 30 Days
A9: Soumyadip Deb | B9: soumyadip.deb@zupee.in | C9: 45484 | E9: Suspend | G9: NOT_FOUND | H9: Mail does not exist in GWS | I9: ✅ | J9: ✅ | K9: ✅ | L9: ❌ | M9: ❌ | N9: ❌ | O9: ❌ | P9: ❌ | Q9: ❌ | T9: > 30 Days
A10: Pankaj Sharma | B10: pankaj.sharma@zupee.in | C10: 45515 | E10: Suspend | G10: NOT_FOUND | H10: Mail does not exist in GWS | I10: ✅ | J10: ✅ | K10: ❌ | L10: ❌ | M10: ❌ | N10: ❌ | O10: ❌ | P10: ❌ | Q10: ❌ | T10: > 30 Days
A11: Anshu Satheesh | B11: anshu.satheesh@zupee.in | C11: 45515 | E11: Suspend | G11: NOT_FOUND | H11: Mail does not exist in GWS | I11: ✅ | J11: ✅ | K11: ❌ | L11: ❌ | M11: ❌ | N11: ❌ | O11: ❌ | P11: ❌ | Q11: ❌ | T11: > 30 Days
A12: Mehul Shah | B12: mehul.shah@zupee.in | C12: 45515 | E12: Suspend | G12: NOT_FOUND | H12: Mail does not exist in GWS | I12: ✅ | J12: ❌ | K12: ✅ | L12: ❌ | M12: ❌ | N12: ❌ | O12: ❌ | P12: ❌ | Q12: ❌ | T12: > 30 Days
A13: Rajashekhar Nari | B13: rajashekhar.nari@zupee.in | C13: 45554 | E13: Suspend | G13: NOT_FOUND | H13: Mail does not exist in GWS | I13: ✅ | J13: ❌ | K13: ✅ | L13: ❌ | M13: ❌ | N13: ❌ | O13: ❌ | P13: ❌ | Q13: ❌ | T13: > 30 Days
A14: Chandan Dwivedi | B14: chandan.dwivedi@zupee.in | C14: 45562 | E14: Suspend | G14: NOT_FOUND | H14: Mail does not exist in GWS | I14: ✅ | J14: ✅ | K14: ✅ | L14: ❌ | M14: ❌ | N14: ❌ | O14: ❌ | P14: ❌ | Q14: ❌ | T14: > 30 Days
A15: Mohit Bakshi | B15: Mohit.bakshi@zupee.in | C15: 45562 | E15: Suspend | G15: NOT_FOUND | H15: Mail does not exist in GWS | I15: ✅ | J15: ❌ | K15: ✅ | L15: ❌ | M15: ❌ | N15: ❌ | O15: ❌ | P15: ✅ | Q15: ❌ | T15: > 30 Days
A16: Ashmita Dwivedi | B16: Ashmita.Dwivedi@zupee.in | C16: 45565 | E16: Suspend | G16: NOT_FOUND | H16: Mail does not exist in GWS | I16: ✅ | J16: ❌ | K16: ✅ | L16: ❌ | M16: ❌ | N16: ❌ | O16: ✅ | P16: ❌ | Q16: ❌ | T16: > 30 Days
A17: Nidhi agarwal | B17: Nidhi.agarwal@zupee.in | C17: 45565 | E17: Suspend | G17: NOT_FOUND | H17: Mail does not exist in GWS | I17: ✅ | J17: ❌ | K17: #️⃣ | L17: ❌ | M17: ❌ | N17: ❌ | O17: ✅ | P17: ✅ | Q17: ❌ | S17: Jira, due to Admin Access | T17: > 30 Days
A18: Sundeep Sharma | B18: sundeep.sharma@zupee.in | C18: 45582 | E18: Suspend | G18: NOT_FOUND | H18: Mail does not exist in GWS | I18: ✅ | J18: ❌ | K18: ✅ | L18: ✅ | M18: ❌ | N18: ❌ | O18: ✅ | P18: ✅ | Q18: ✅ | T18: > 30 Days
A19: Samir Halder External | B19: samir.halder@zupee.in | C19: 45582 | E19: Suspend | G19: NOT_FOUND | H19: Mail does not exist in GWS | I19: ❌ | J19: ❌ | K19: ❌ | L19: ❌ | M19: ✅ | N19: ❌ | O19: ❌ | P19: ❌ | Q19: ❌ | T19: > 30 Days
A20: Prakash Vedvyas Acharya | B20: prakash.acharya@zupee.in | C20: 45586 | E20: Suspend | G20: NOT_FOUND | H20: Mail does not exist in GWS | I20: ✅ | J20: ❌ | K20: ❌ | L20: ❌ | M20: ❌ | N20: ❌ | O20: ❌ | P20: ❌ | Q20: ❌ | T20: > 30 Days
A21: Shubham Vishwakarma | B21: shubham.vishwakarma@zupee.in | C21: 45590 | E21: Suspend | G21: NOT_FOUND | H21: Mail does not exist in GWS | I21: ✅ | J21: ✅ | K21: ✅ | L21: ❌ | M21: ❌ | N21: ❌ | O21: ❌ | P21: ✅ | Q21: ❌ | T21: > 30 Days
A22: Harsh Mehta | B22: harsh.mehta@zupee.in | C22: 45591 | E22: Suspend | G22: NOT_FOUND | H22: Mail does not exist in GWS | I22: ✅ | J22: ✅ | K22: ❌ | L22: ❌ | M22: ❌ | N22: ❌ | O22: ❌ | P22: ❌ | Q22: ❌ | T22: > 30 Days
A23: Shreyansh Bengani | B23: shreyansh.bengani@zupee.in | C23: 45593 | E23: Suspend | G23: NOT_FOUND | H23: Mail does not exist in GWS | I23: ✅ | J23: ✅ | K23: ✅ | L23: ❌ | M23: ❌ | N23: ❌ | O23: ❌ | P23: ✅ | Q23: ❌ | T23: > 30 Days
A24: Nitin Kumar | B24: nitin.kumar@zupee.in | C24: 45594 | E24: Suspend | G24: NOT_FOUND | H24: Mail does not exist in GWS | I24: ❌ | J24: ❌ | K24: ❌ | L24: ❌ | M24: ❌ | N24: ❌ | O24: ❌ | P24: ❌ | Q24: ❌ | T24: > 30 Days
A25: Deepak Dahiya | B25: deepak.dahiya@zupee.in | C25: 45606 | E25: Suspend | G25: NOT_FOUND | H25: Mail does not exist in GWS | I25: ✅ | J25: ✅ | K25: ❌ | L25: ❌ | M25: ❌ | N25: ❌ | O25: ❌ | P25: ❌ | Q25: ❌ | T25: > 30 Days
A26: Shivangi | B26: shivangi.shivangi@zupee.in | C26: 45607 | E26: Suspend | G26: NOT_FOUND | H26: Mail does not exist in GWS | I26: ✅ | J26: ❌ | K26: ❌ | L26: ❌ | M26: ❌ | N26: ❌ | O26: ❌ | P26: ❌ | Q26: ✅ | T26: > 30 Days
A27: Anita Rane | B27: anita.rane@zupee.in | C27: 45610 | E27: Suspend | G27: NOT_FOUND | H27: Mail does not exist in GWS | I27: ✅ | J27: ❌ | K27: ❌ | L27: ❌ | M27: ❌ | N27: ❌ | O27: ❌ | P27: ❌ | Q27: ❌ | T27: > 30 Days
A28: Nikhil Jha | B28: nikhil.jha@zupee.in | C28: 45610 | E28: Suspend | G28: NOT_FOUND | H28: Mail does not exist in GWS | I28: ✅ | J28: ❌ | K28: ✅ | L28: ✅ | M28: ✅ | N28: ❌ | O28: ❌ | P28: ❌ | Q28: ❌ | T28: > 30 Days
A29: Anjali Rai | B29: anjali.rai@zupee.in | C29: 45614 | E29: Suspend | G29: NOT_FOUND | H29: Mail does not exist in GWS | I29: ✅ | J29: ✅ | K29: ❌ | L29: ❌ | M29: ❌ | N29: ❌ | O29: ✅ | P29: ❌ | Q29: ❌ | T29: > 30 Days
... A34: Sonam Rathore | B34: sonam.rathore@zupee.in | C34: 45625 | E34: Suspend | G34: NOT_FOUND | H34: Mail does not exist in GWS | I34: ✅ | J34: ✅ | K34: ✅ | L34: ✅ | M34: ❌ | N34: ❌ | O34: ❌ | P34: ✅ | Q34: ✅ | T34: > 30 Days
A35: Manav Mukesh Jain | B35: manav.jain@zupee.in | C35: 45625 | E35: =VLOOKUP(B35,AT_Data!A:D,4,0) -> Hold | F35: =VLOOKUP(B35,'On-Boarding'!C:D,2,0) -> Org | G35: SUSPENDED | H35: User is SUSPENDED | I35: ✅ | J35: ✅ | K35: ❌ | L35: ❌ | M35: ❌ | N35: ❌ | O35: ❌ | P35: ❌ | Q35: ✅ | T35: > 30 Days
A36: Varsha SK | B36: varsha.sk@zupee.in | C36: 45628 | E36: Suspend | G36: NOT_FOUND | H36: Mail does not exist in GWS | I36: ✅ | J36: ❌ | K36: ❌ | L36: ❌ | M36: ❌ | N36: ❌ | O36: ✅ | P36: ❌ | Q36: ❌ | T36: > 30 Days
A37: Akshit kumar | B37: Akshit.Kumar@zupee.in | C37: 45629 | E37: Suspend | G37: NOT_FOUND | H37: Mail does not exist in GWS | I37: ✅ | J37: ❌ | K37: ✅ | L37: ❌ | M37: ❌ | N37: ❌ | O37: ❌ | P37: ❌ | Q37: ❌ | T37: > 30 Days
A38: Rupam Das | B38: rupam.das@zupee.in | C38: 45630 | E38: Suspend | G38: NOT_FOUND | H38: Mail does not exist in GWS | I38: ✅ | J38: ✅ | K38: ✅ | L38: ❌ | M38: ❌ | N38: ❌ | O38: ❌ | P38: ✅ | Q38: ✅ | T38: > 30 Days
A39: Sonam Gupta | B39: sonam.gupta@zupee.in | C39: 45635 | E39: Suspend | G39: NOT_FOUND | H39: Mail does not exist in GWS | I39: ✅ | J39: ❌ | K39: ❌ | L39: ❌ | M39: ❌ | N39: ❌ | O39: ❌ | P39: ✅ | Q39: ✅ | T39: > 30 Days
A40: Neha Sharma | B40: neha.sharma@zupee.in | C40: 45639 | E40: Suspend | G40: NOT_FOUND | H40: Mail does not exist in GWS | I40: ✅ | J40: ❌ | K40: ✅ | L40: ❌ | M40: ❌ | N40: ❌ | O40: ❌ | P40: ❌ | Q40: ❌ | T40: > 30 Days
A41: Nishchay Singh | B41: nishchay.singh@zupee.in | C41: 45642 | E41: Suspend | G41: NOT_FOUND | H41: Mail does not exist in GWS | I41: ✅ | J41: ❌ | K41: ✅ | L41: ❌ | M41: ❌ | N41: ❌ | O41: ❌ | P41: ✅ | Q41: ✅ | T41: > 30 Days
A42: Aryan Gupta | B42: aryan.gupta@zupee.in | C42: 45646 | E42: Suspend | G42: NOT_FOUND | H42: Mail does not exist in GWS | I42: ✅ | J42: ❌ | K42: ✅ | L42: ❌ | M42: ❌ | N42: ❌ | O42: ❌ | P42: ❌ | Q42: ✅ | T42: > 30 Days
A43: Himanshu Grover | B43: himanshu.grover@zupee.in | C43: 45650 | E43: Suspend | G43: NOT_FOUND | H43: Mail does not exist in GWS | I43: ✅ | J43: ❌ | K43: ✅ | L43: ❌ | M43: ❌ | N43: ❌ | O43: ❌ | P43: ❌ | Q43: ✅ | T43: > 30 Days
A44: Yash Anand | B44: yash.anand@zupee.in | C44: 45650 | E44: Suspend | G44: NOT_FOUND | H44: Mail does not exist in GWS | I44: ✅ | J44: ❌ | K44: ✅ | L44: ❌ | M44: ❌ | N44: ❌ | O44: ❌ | P44: ❌ | Q44: ❌ | T44: > 30 Days
...

Sheet Join & Induc By HR
B1: CANDIDATE DETAILS
A2: =IFERROR(__xludf.DUMMYFUNCTION("QUERY(IMPORTRANGE(""1xFrklApkRqApw6hS49w9Le1ELcHrQ5f2FJdiVs8ztHg"", ""Joining & Induction Tracker!A:Z""), ""SELECT Col10, Col1, Col3, Col5, Col2, Col4, Col6, Col7, Col9, Col12, Col13, Col14, Col25, Col26"") ")," Probable Date of Joining") -> Probable Date of Joining | B2: =IFERROR(__xludf.DUMMYFUNCTION("""COMPUTED_VALUE""")," Name") -> Name | C2: =IFERROR(__xludf.DUMMYFUNCTION("""COMPUTED_VALUE""")," Department") -> Department | D2: =IFERROR(__xludf.DUMMYFUNCTION("""COMPUTED_VALUE""")," Contact Number") -> Contact Number | E2: =IFERROR(__xludf.DUMMYFUNCTION("""COMPUTED_VALUE"""),"CANDIDATE DETAILS Designation") -> CANDIDATE DETAILS Designation | F2: =IFERROR(__xludf.DUMMYFUNCTION("""COMPUTED_VALUE""")," Sub Department ") -> Sub Department | G2: =IFERROR(__xludf.DUMMYFUNCTION("""COMPUTED_VALUE""")," Personal Email ID") -> Personal Email ID | H2: =IFERROR(__xludf.DUMMYFUNCTION("""COMPUTED_VALUE""")," Reporting Manager") -> Reporting Manager | I2: =IFERROR(__xludf.DUMMYFUNCTION("""COMPUTED_VALUE""")," Date of Offer Release") -> Date of Offer Release | J2: =IFERROR(__xludf.DUMMYFUNCTION("""COMPUTED_VALUE""")," Recruiter Name") -> Recruiter Name | K2: =IFERROR(__xludf.DUMMYFUNCTION("""COMPUTED_VALUE""")," Offer Status") -> Offer Status | L2: =IFERROR(__xludf.DUMMYFUNCTION("""COMPUTED_VALUE""")," Induction Type") -> Induction Type | M2: =IFERROR(__xludf.DUMMYFUNCTION("""COMPUTED_VALUE"""),"To be Filled by IT Team Email ID") -> To be Filled by IT Team Email ID | N2: =IFERROR(__xludf.DUMMYFUNCTION("""COMPUTED_VALUE""")," Laptop Allocated Serial Number") -> Laptop Allocated Serial Number
A3: =IFERROR(__xludf.DUMMYFUNCTION("""COMPUTED_VALUE"""),45170.0) -> 45170 | B3: =IFERROR(__xludf.DUMMYFUNCTION("""COMPUTED_VALUE"""),"Shikhar Varshney") -> Shikhar Varshney | C3: =IFERROR(__xludf.DUMMYFUNCTION("""COMPUTED_VALUE"""),"Corporate") -> Corporate | D3: =IFERROR(__xludf.DUMMYFUNCTION("""COMPUTED_VALUE"""),8.449159038E9) -> 8449159038 | E3: =IFERROR(__xludf.DUMMYFUNCTION("""COMPUTED_VALUE"""),"Market Research Intern") -> Market Research Intern | F3: =IFERROR(__xludf.DUMMYFUNCTION("""COMPUTED_VALUE"""),"Strategy") -> Strategy | G3: =IFERROR(__xludf.DUMMYFUNCTION("""COMPUTED_VALUE""")," shikharvarshney03@gmail.com") -> shikharvarshney03@gmail.com | H3: =IFERROR(__xludf.DUMMYFUNCTION("""COMPUTED_VALUE"""),"Nishchay Singh ") -> Nishchay Singh | I3: =IFERROR(__xludf.DUMMYFUNCTION("""COMPUTED_VALUE"""),45167.0) -> 45167 | J3: =IFERROR(__xludf.DUMMYFUNCTION("""COMPUTED_VALUE"""),"Naina") -> Naina | K3: =IFERROR(__xludf.DUMMYFUNCTION("""COMPUTED_VALUE"""),"Joined") -> Joined | L3: =IFERROR(__xludf.DUMMYFUNCTION("""COMPUTED_VALUE"""),"In Office") -> In Office | M3: =IFERROR(__xludf.DUMMYFUNCTION("""COMPUTED_VALUE"""),"shikhar.varshney@zupee.in") -> shikhar.varshney@zupee.in
A4: =IFERROR(__xludf.DUMMYFUNCTION("""COMPUTED_VALUE"""),45173.0) -> 45173 | B4: =IFERROR(__xludf.DUMMYFUNCTION("""COMPUTED_VALUE"""),"Shaurya Upadhyay") -> Shaurya Upadhyay | C4: =IFERROR(__xludf.DUMMYFUNCTION("""COMPUTED_VALUE"""),"Technology") -> Technology | D4: =IFERROR(__xludf.DUMMYFUNCTION("""COMPUTED_VALUE"""),9.818418781E9) -> 9818418781 | E4: =IFERROR(__xludf.DUMMYFUNCTION("""COMPUTED_VALUE"""),"Security Engineer Trainee") -> Security Engineer Trainee | F4: =IFERROR(__xludf.DUMMYFUNCTION("""COMPUTED_VALUE"""),"Engineering") -> Engineering | G4: =IFERROR(__xludf.DUMMYFUNCTION("""COMPUTED_VALUE"""),"shauryaupadhyay59@gmail.com ") -> shauryaupadhyay59@gmail.com | H4: =IFERROR(__xludf.DUMMYFUNCTION("""COMPUTED_VALUE"""),"Shreyansh Bengani") -> Shreyansh Bengani | J4: =IFERROR(__xludf.DUMMYFUNCTION("""COMPUTED_VALUE"""),"Mamta Pandey") -> Mamta Pandey | K4: =IFERROR(__xludf.DUMMYFUNCTION("""COMPUTED_VALUE"""),"Joined") -> Joined | L4: =IFERROR(__xludf.DUMMYFUNCTION("""COMPUTED_VALUE"""),"In Office") -> In Office | M4: =IFERROR(__xludf.DUMMYFUNCTION("""COMPUTED_VALUE"""),"shaurya.upadhyay@zupee.in") -> shaurya.upadhyay@zupee.in
A5: =IFERROR(__xludf.DUMMYFUNCTION("""COMPUTED_VALUE"""),45174.0) -> 45174 | B5: =IFERROR(__xludf.DUMMYFUNCTION("""COMPUTED_VALUE"""),"Nikunj Aggarwal") -> Nikunj Aggarwal | C5: =IFERROR(__xludf.DUMMYFUNCTION("""COMPUTED_VALUE"""),"Technology") -> Technology | D5: =IFERROR(__xludf.DUMMYFUNCTION("""COMPUTED_VALUE"""),9.810210616E9) -> 9810210616 | E5: =IFERROR(__xludf.DUMMYFUNCTION("""COMPUTED_VALUE"""),"Software Engineer - Android") -> Software Engineer - Android | F5: =IFERROR(__xludf.DUMMYFUNCTION("""COMPUTED_VALUE"""),"Engineering") -> Engineering | G5: =IFERROR(__xludf.DUMMYFUNCTION("""COMPUTED_VALUE"""),"annikunjagg@gmail.com") -> annikunjagg@gmail.com | H5: =IFERROR(__xludf.DUMMYFUNCTION("""COMPUTED_VALUE"""),"Anshul Mittal") -> Anshul Mittal | I5: =IFERROR(__xludf.DUMMYFUNCTION("""COMPUTED_VALUE"""),45163.0) -> 45163 | J5: =IFERROR(__xludf.DUMMYFUNCTION("""COMPUTED_VALUE"""),"Naina") -> Naina | K5: =IFERROR(__xludf.DUMMYFUNCTION("""COMPUTED_VALUE"""),"Joined") -> Joined | L5: =IFERROR(__xludf.DUMMYFUNCTION("""COMPUTED_VALUE"""),"In Office") -> In Office | M5: =IFERROR(__xludf.DUMMYFUNCTION("""COMPUTED_VALUE"""),"nikunj.aggarwal@zupee.in") -> nikunj.aggarwal@zupee.in
A6: =IFERROR(__xludf.DUMMYFUNCTION("""COMPUTED_VALUE"""),45182.0) -> 45182 | B6: =IFERROR(__xludf.DUMMYFUNCTION("""COMPUTED_VALUE"""),"Rakesh Kumar") -> Rakesh Kumar | C6: =IFERROR(__xludf.DUMMYFUNCTION("""COMPUTED_VALUE"""),"Corporate") -> Corporate | D6: =IFERROR(__xludf.DUMMYFUNCTION("""COMPUTED_VALUE"""),7.999002836E9) -> 7999002836 | E6: =IFERROR(__xludf.DUMMYFUNCTION("""COMPUTED_VALUE"""),"IT Executive") -> IT Executive | F6: =IFERROR(__xludf.DUMMYFUNCTION("""COMPUTED_VALUE"""),"Administration") -> Administration | G6: =IFERROR(__xludf.DUMMYFUNCTION("""COMPUTED_VALUE"""),"rakeshkumarrk35386@gmail.com") -> rakeshkumarrk35386@gmail.com | H6: =IFERROR(__xludf.DUMMYFUNCTION("""COMPUTED_VALUE"""),"Naveen Kumar") -> Naveen Kumar | J6: =IFERROR(__xludf.DUMMYFUNCTION("""COMPUTED_VALUE"""),"Mamta Pandey") -> Mamta Pandey | K6: =IFERROR(__xludf.DUMMYFUNCTION("""COMPUTED_VALUE"""),"Joined") -> Joined | L6: =IFERROR(__xludf.DUMMYFUNCTION("""COMPUTED_VALUE"""),"In Office") -> In Office | M6: =IFERROR(__xludf.DUMMYFUNCTION("""COMPUTED_VALUE"""),"rakesh.kumar@zupee.in") -> rakesh.kumar@zupee.in | N6: =IFERROR(__xludf.DUMMYFUNCTION("""COMPUTED_VALUE"""),"JZV7VQ3") -> JZV7VQ3
A7: =IFERROR(__xludf.DUMMYFUNCTION("""COMPUTED_VALUE"""),45189.0) -> 45189 | B7: =IFERROR(__xludf.DUMMYFUNCTION("""COMPUTED_VALUE"""),"Tushar Sharma") -> Tushar Sharma | C7: =IFERROR(__xludf.DUMMYFUNCTION("""COMPUTED_VALUE"""),"Corporate") -> Corporate | D7: =IFERROR(__xludf.DUMMYFUNCTION("""COMPUTED_VALUE"""),8.851799414E9) -> 8851799414 | E7: =IFERROR(__xludf.DUMMYFUNCTION("""COMPUTED_VALUE"""),"Senior Finance Executive") -> Senior Finance Executive | F7: =IFERROR(__xludf.DUMMYFUNCTION("""COMPUTED_VALUE"""),"Finance") -> Finance | G7: =IFERROR(__xludf.DUMMYFUNCTION("""COMPUTED_VALUE"""),"Tushar2419@yahoo.com") -> Tushar2419@yahoo.com | H7: =IFERROR(__xludf.DUMMYFUNCTION("""COMPUTED_VALUE"""),"Hitesh Vats") -> Hitesh Vats | J7: =IFERROR(__xludf.DUMMYFUNCTION("""COMPUTED_VALUE"""),"Nidhi Khedekar") -> Nidhi Khedekar | K7: =IFERROR(__xludf.DUMMYFUNCTION("""COMPUTED_VALUE"""),"Joined") -> Joined | L7: =IFERROR(__xludf.DUMMYFUNCTION("""COMPUTED_VALUE"""),"In Office") -> In Office | M7: =IFERROR(__xludf.DUMMYFUNCTION("""COMPUTED_VALUE"""),"tushar.sharma@zupee.in") -> tushar.sharma@zupee.in
A8: =IFERROR(__xludf.DUMMYFUNCTION("""COMPUTED_VALUE"""),45202.0) -> 45202 | B8: =IFERROR(__xludf.DUMMYFUNCTION("""COMPUTED_VALUE"""),"Ashvani Kumar") -> Ashvani Kumar | C8: =IFERROR(__xludf.DUMMYFUNCTION("""COMPUTED_VALUE"""),"Customer Experience") -> Customer Experience | D8: =IFERROR(__xludf.DUMMYFUNCTION("""COMPUTED_VALUE"""),9.149230623E9) -> 9149230623 | E8: =IFERROR(__xludf.DUMMYFUNCTION("""COMPUTED_VALUE"""),"Fraud Analyst") -> Fraud Analyst | F8: =IFERROR(__xludf.DUMMYFUNCTION("""COMPUTED_VALUE"""),"Fraud Risk Management ") -> Fraud Risk Management | G8: =IFERROR(__xludf.DUMMYFUNCTION("""COMPUTED_VALUE"""),"ashvanikumar180210@gmail.com") -> ashvanikumar180210@gmail.com | H8: =IFERROR(__xludf.DUMMYFUNCTION("""COMPUTED_VALUE"""),"Aman Khare") -> Aman Khare | J8: =IFERROR(__xludf.DUMMYFUNCTION("""COMPUTED_VALUE"""),"Nidhi Khedekar") -> Nidhi Khedekar | K8: =IFERROR(__xludf.DUMMYFUNCTION("""COMPUTED_VALUE"""),"Joined") -> Joined | L8: =IFERROR(__xludf.DUMMYFUNCTION("""COMPUTED_VALUE"""),"In Office") -> In Office
A9: =IFERROR(__xludf.DUMMYFUNCTION("""COMPUTED_VALUE"""),45203.0) -> 45203 | B9: =IFERROR(__xludf.DUMMYFUNCTION("""COMPUTED_VALUE"""),"Rahul Bhatia") -> Rahul Bhatia | C9: =IFERROR(__xludf.DUMMYFUNCTION("""COMPUTED_VALUE"""),"Corporate") -> Corporate | D9: =IFERROR(__xludf.DUMMYFUNCTION("""COMPUTED_VALUE"""),9.2682085E9) -> 9268208500 | E9: =IFERROR(__xludf.DUMMYFUNCTION("""COMPUTED_VALUE"""),"Senior Finance Executive") -> Senior Finance Executive | F9: =IFERROR(__xludf.DUMMYFUNCTION("""COMPUTED_VALUE"""),"Finance") -> Finance | G9: =IFERROR(__xludf.DUMMYFUNCTION("""COMPUTED_VALUE"""),"rahul13bhatia@gmail.com") -> rahul13bhatia@gmail.com | H9: =IFERROR(__xludf.DUMMYFUNCTION("""COMPUTED_VALUE"""),"Sunil Gupta") -> Sunil Gupta | I9: =IFERROR(__xludf.DUMMYFUNCTION("""COMPUTED_VALUE"""),45147.0) -> 45147 | J9: =IFERROR(__xludf.DUMMYFUNCTION("""COMPUTED_VALUE"""),"Nidhi Khedekar") -> Nidhi Khedekar | K9: =IFERROR(__xludf.DUMMYFUNCTION("""COMPUTED_VALUE"""),"Offer Revoked") -> Offer Revoked | L9: =IFERROR(__xludf.DUMMYFUNCTION("""COMPUTED_VALUE"""),"Drop Out") -> Drop Out
A10: =IFERROR(__xludf.DUMMYFUNCTION("""COMPUTED_VALUE"""),45215.0) -> 45215 | B10: =IFERROR(__xludf.DUMMYFUNCTION("""COMPUTED_VALUE"""),"Amit Singh") -> Amit Singh | C10: =IFERROR(__xludf.DUMMYFUNCTION("""COMPUTED_VALUE"""),"Technology") -> Technology | D10: =IFERROR(__xludf.DUMMYFUNCTION("""COMPUTED_VALUE"""),9.711112881E9) -> 9711112881 | E10: =IFERROR(__xludf.DUMMYFUNCTION("""COMPUTED_VALUE"""),"Senior Staff Engineer") -> Senior Staff Engineer | F10: =IFERROR(__xludf.DUMMYFUNCTION("""COMPUTED_VALUE"""),"Engineering") -> Engineering | G10: =IFERROR(__xludf.DUMMYFUNCTION("""COMPUTED_VALUE"""),"amitabesit@gmail.com") -> amitabesit@gmail.com | H10: =IFERROR(__xludf.DUMMYFUNCTION("""COMPUTED_VALUE"""),"Ranjeet Kumar") -> Ranjeet Kumar | I10: =IFERROR(__xludf.DUMMYFUNCTION("""COMPUTED_VALUE"""),45211.0) -> 45211 | J10: =IFERROR(__xludf.DUMMYFUNCTION("""COMPUTED_VALUE"""),"Rajneesh Yadav") -> Rajneesh Yadav | K10: =IFERROR(__xludf.DUMMYFUNCTION("""COMPUTED_VALUE"""),"Joined") -> Joined | L10: =IFERROR(__xludf.DUMMYFUNCTION("""COMPUTED_VALUE"""),"In Office") -> In Office | M10: =IFERROR(__xludf.DUMMYFUNCTION("""COMPUTED_VALUE"""),"amit.singh@zupee.in") -> amit.singh@zupee.in | N10: =IFERROR(__xludf.DUMMYFUNCTION("""COMPUTED_VALUE"""),"VYCVM29T75") -> VYCVM29T75
A11: =IFERROR(__xludf.DUMMYFUNCTION("""COMPUTED_VALUE"""),45215.0) -> 45215 | B11: =IFERROR(__xludf.DUMMYFUNCTION("""COMPUTED_VALUE"""),"Manmohan Sagar") -> Manmohan Sagar | C11: =IFERROR(__xludf.DUMMYFUNCTION("""COMPUTED_VALUE"""),"Finance") -> Finance | D11: =IFERROR(__xludf.DUMMYFUNCTION("""COMPUTED_VALUE"""),8.800739621E9) -> 8800739621 | E11: =IFERROR(__xludf.DUMMYFUNCTION("""COMPUTED_VALUE"""),"Senior Executive- Finance") -> Senior Executive- Finance | F11: =IFERROR(__xludf.DUMMYFUNCTION("""COMPUTED_VALUE"""),"Finance") -> Finance | G11: =IFERROR(__xludf.DUMMYFUNCTION("""COMPUTED_VALUE"""),"Manmohansagar97@gmail.com") -> Manmohansagar97@gmail.com | H11: =IFERROR(__xludf.DUMMYFUNCTION("""COMPUTED_VALUE"""),"Vikas Gupta") -> Vikas Gupta | J11: =IFERROR(__xludf.DUMMYFUNCTION("""COMPUTED_VALUE"""),"Nidhi Khedekar") -> Nidhi Khedekar | K11: =IFERROR(__xludf.DUMMYFUNCTION("""COMPUTED_VALUE"""),"Joined") -> Joined | L11: =IFERROR(__xludf.DUMMYFUNCTION("""COMPUTED_VALUE"""),"In Office") -> In Office | M11: =IFERROR(__xludf.DUMMYFUNCTION("""COMPUTED_VALUE"""),"manmohan.sagar@zupee.in") -> manmohan.sagar@zupee.in | N11: =IFERROR(__xludf.DUMMYFUNCTION("""COMPUTED_VALUE"""),"8J9FCY3") -> 8J9FCY3
A12: =IFERROR(__xludf.DUMMYFUNCTION("""COMPUTED_VALUE"""),45217.0) -> 45217 | B12: =IFERROR(__xludf.DUMMYFUNCTION("""COMPUTED_VALUE"""),"Pratik Taltia") -> Pratik Taltia | C12: =IFERROR(__xludf.DUMMYFUNCTION("""COMPUTED_VALUE"""),"Marketing") -> Marketing | D12: =IFERROR(__xludf.DUMMYFUNCTION("""COMPUTED_VALUE"""),7.358433457E9) -> 7358433457 | E12: =IFERROR(__xludf.DUMMYFUNCTION("""COMPUTED_VALUE"""),"Product Marketing Executive") -> Product Marketing Executive | F12: =IFERROR(__xludf.DUMMYFUNCTION("""COMPUTED_VALUE"""),"Digital Marketing") -> Digital Marketing | G12: =IFERROR(__xludf.DUMMYFUNCTION("""COMPUTED_VALUE"""),"pratiktaltia.a@gmail.com") -> pratiktaltia.a@gmail.com | H12: =IFERROR(__xludf.DUMMYFUNCTION("""COMPUTED_VALUE"""),"Aditya Jha") -> Aditya Jha | J12: =IFERROR(__xludf.DUMMYFUNCTION("""COMPUTED_VALUE"""),"Nidhi Khedekar") -> Nidhi Khedekar | K12: =IFERROR(__xludf.DUMMYFUNCTION("""COMPUTED_VALUE"""),"Joined") -> Joined | L12: =IFERROR(__xludf.DUMMYFUNCTION("""COMPUTED_VALUE"""),"In Office") -> In Office | M12: =IFERROR(__xludf.DUMMYFUNCTION("""COMPUTED_VALUE"""),"pratik.taltia@zupee.in") -> pratik.taltia@zupee.in | N12: =IFERROR(__xludf.DUMMYFUNCTION("""COMPUTED_VALUE"""),"KG667421QL") -> KG667421QL
A13: =IFERROR(__xludf.DUMMYFUNCTION("""COMPUTED_VALUE"""),45222.0) -> 45222 | B13: =IFERROR(__xludf.DUMMYFUNCTION("""COMPUTED_VALUE"""),"Awadhesh Singh Tanwar") -> Awadhesh Singh Tanwar | C13: =IFERROR(__xludf.DUMMYFUNCTION("""COMPUTED_VALUE"""),"Technology") -> Technology | D13: =IFERROR(__xludf.DUMMYFUNCTION("""COMPUTED_VALUE"""),9.479456993E9) -> 9479456993 | E13: =IFERROR(__xludf.DUMMYFUNCTION("""COMPUTED_VALUE"""),"Senior Data Engineer") -> Senior Data Engineer | F13: =IFERROR(__xludf.DUMMYFUNCTION("""COMPUTED_VALUE"""),"Data Engineering") -> Data Engineering | G13: =IFERROR(__xludf.DUMMYFUNCTION("""COMPUTED_VALUE"""),"dapst8@gmail.com") -> dapst8@gmail.com | H13: =IFERROR(__xludf.DUMMYFUNCTION("""COMPUTED_VALUE"""),"Aman Bahl") -> Aman Bahl | I13: =IFERROR(__xludf.DUMMYFUNCTION("""COMPUTED_VALUE"""),45129.0) -> 45129 | J13: =IFERROR(__xludf.DUMMYFUNCTION("""COMPUTED_VALUE"""),"Nidhi Khedekar") -> Nidhi Khedekar | K13: =IFERROR(__xludf.DUMMYFUNCTION("""COMPUTED_VALUE"""),"Offer Declined") -> Offer Declined | L13: =IFERROR(__xludf.DUMMYFUNCTION("""COMPUTED_VALUE"""),"In Office") -> In Office
A14: =IFERROR(__xludf.DUMMYFUNCTION("""COMPUTED_VALUE"""),45237.0) -> 45237 | B14: =IFERROR(__xludf.DUMMYFUNCTION("""COMPUTED_VALUE"""),"Pradeep Agrawal") -> Pradeep Agrawal | C14: =IFERROR(__xludf.DUMMYFUNCTION("""COMPUTED_VALUE"""),"Technology") -> Technology | D14: =IFERROR(__xludf.DUMMYFUNCTION("""COMPUTED_VALUE"""),9.782015101E9) -> 9782015101 | E14: =IFERROR(__xludf.DUMMYFUNCTION("""COMPUTED_VALUE"""),"Lead Data Engineer") -> Lead Data Engineer | F14: =IFERROR(__xludf.DUMMYFUNCTION("""COMPUTED_VALUE"""),"Data Engineering") -> Data Engineering | G14: =IFERROR(__xludf.DUMMYFUNCTION("""COMPUTED_VALUE"""),"pradeepagrawalan1994@gmail.com") -> pradeepagrawalan1994@gmail.com | H14: =IFERROR(__xludf.DUMMYFUNCTION("""COMPUTED_VALUE"""),"Aman Bahl") -> Aman Bahl | J14: =IFERROR(__xludf.DUMMYFUNCTION("""COMPUTED_VALUE"""),"Naina") -> Naina | K14: =IFERROR(__xludf.DUMMYFUNCTION("""COMPUTED_VALUE"""),"Joined") -> Joined | L14: =IFERROR(__xludf.DUMMYFUNCTION("""COMPUTED_VALUE"""),"In Office") -> In Office | M14: =IFERROR(__xludf.DUMMYFUNCTION("""COMPUTED_VALUE"""),"pradeep.agrawal@zupee.in") -> pradeep.agrawal@zupee.in
A15: =IFERROR(__xludf.DUMMYFUNCTION("""COMPUTED_VALUE"""),45265.0) -> 45265 | B15: =IFERROR(__xludf.DUMMYFUNCTION("""COMPUTED_VALUE"""),"Abhishek Goyal") -> Abhishek Goyal | C15: =IFERROR(__xludf.DUMMYFUNCTION("""COMPUTED_VALUE"""),"Product") -> Product | D15: =IFERROR(__xludf.DUMMYFUNCTION("""COMPUTED_VALUE"""),7.974831301E9) -> 7974831301 | E15: =IFERROR(__xludf.DUMMYFUNCTION("""COMPUTED_VALUE"""),"Manager - Strategy") -> Manager - Strategy | F15: =IFERROR(__xludf.DUMMYFUNCTION("""COMPUTED_VALUE"""),"Strategy") -> Strategy | G15: =IFERROR(__xludf.DUMMYFUNCTION("""COMPUTED_VALUE"""),"goyal.abhishek28@gmail.com") -> goyal.abhishek28@gmail.com | H15: =IFERROR(__xludf.DUMMYFUNCTION("""COMPUTED_VALUE"""),"Ishank Mehta") -> Ishank Mehta | J15: =IFERROR(__xludf.DUMMYFUNCTION("""COMPUTED_VALUE"""),"Naina") -> Naina | K15: =IFERROR(__xludf.DUMMYFUNCTION("""COMPUTED_VALUE"""),"Joined") -> Joined | L15: =IFERROR(__xludf.DUMMYFUNCTION("""COMPUTED_VALUE"""),"In Office") -> In Office | M15: =IFERROR(__xludf.DUMMYFUNCTION("""COMPUTED_VALUE"""),"abhishek.goyal@zupee.in") -> abhishek.goyal@zupee.in | N15: =IFERROR(__xludf.DUMMYFUNCTION("""COMPUTED_VALUE"""),"GY1HHJ5H96") -> GY1HHJ5H96
A16: =IFERROR(__xludf.DUMMYFUNCTION("""COMPUTED_VALUE"""),45236.0) -> 45236 | B16: =IFERROR(__xludf.DUMMYFUNCTION("""COMPUTED_VALUE"""),"Sujoy Ghosh") -> Sujoy Ghosh | C16: =IFERROR(__xludf.DUMMYFUNCTION("""COMPUTED_VALUE"""),"Product") -> Product | D16: =IFERROR(__xludf.DUMMYFUNCTION("""COMPUTED_VALUE"""),9.739922559E9) -> 9739922559 | E16: =IFERROR(__xludf.DUMMYFUNCTION("""COMPUTED_VALUE"""),"Associate Director- Products") -> Associate Director- Products | F16: =IFERROR(__xludf.DUMMYFUNCTION("""COMPUTED_VALUE"""),"Product") -> Product | G16: =IFERROR(__xludf.DUMMYFUNCTION("""COMPUTED_VALUE"""),"suzoyy@gmail.com") -> suzoyy@gmail.com | H16: =IFERROR(__xludf.DUMMYFUNCTION("""COMPUTED_VALUE"""),"Naveen Kadyan") -> Naveen Kadyan | I16: =IFERROR(__xludf.DUMMYFUNCTION("""COMPUTED_VALUE"""),45218.0) -> 45218 | J16: =IFERROR(__xludf.DUMMYFUNCTION("""COMPUTED_VALUE"""),"M Sangeetha") -> M Sangeetha | K16: =IFERROR(__xludf.DUMMYFUNCTION("""COMPUTED_VALUE"""),"Joined") -> Joined | L16: =IFERROR(__xludf.DUMMYFUNCTION("""COMPUTED_VALUE"""),"In Office") -> In Office | M16: =IFERROR(__xludf.DUMMYFUNCTION("""COMPUTED_VALUE"""),"sujoy.ghosh@zupee.in") -> sujoy.ghosh@zupee.in
A17: =IFERROR(__xludf.DUMMYFUNCTION("""COMPUTED_VALUE"""),45236.0) -> 45236 | B17: =IFERROR(__xludf.DUMMYFUNCTION("""COMPUTED_VALUE"""),"Sanket Jain") -> Sanket Jain | C17: =IFERROR(__xludf.DUMMYFUNCTION("""COMPUTED_VALUE"""),"Product") -> Product | D17: =IFERROR(__xludf.DUMMYFUNCTION("""COMPUTED_VALUE"""),9.818953844E9) -> 9818953844 | E17: =IFERROR(__xludf.DUMMYFUNCTION("""COMPUTED_VALUE"""),"Manager - Strategy") -> Manager - Strategy | F17: =IFERROR(__xludf.DUMMYFUNCTION("""COMPUTED_VALUE"""),"Strategy") -> Strategy | G17: =IFERROR(__xludf.DUMMYFUNCTION("""COMPUTED_VALUE"""),"jain.sanket93@gmail.com") -> jain.sanket93@gmail.com | H17: =IFERROR(__xludf.DUMMYFUNCTION("""COMPUTED_VALUE"""),"Ishank Mehta") -> Ishank Mehta | J17: =IFERROR(__xludf.DUMMYFUNCTION("""COMPUTED_VALUE"""),"Naina") -> Naina | K17: =IFERROR(__xludf.DUMMYFUNCTION("""COMPUTED_VALUE"""),"Joined") -> Joined | L17: =IFERROR(__xludf.DUMMYFUNCTION("""COMPUTED_VALUE"""),"In Office") -> In Office | M17: =IFERROR(__xludf.DUMMYFUNCTION("""COMPUTED_VALUE"""),"sanket.jain@zupee.in") -> sanket.jain@zupee.in
A18: =IFERROR(__xludf.DUMMYFUNCTION("""COMPUTED_VALUE"""),45268.0) -> 45268 | B18: =IFERROR(__xludf.DUMMYFUNCTION("""COMPUTED_VALUE"""),"Mohit Singh Rathore") -> Mohit Singh Rathore | C18: =IFERROR(__xludf.DUMMYFUNCTION("""COMPUTED_VALUE"""),"Technology") -> Technology | D18: =IFERROR(__xludf.DUMMYFUNCTION("""COMPUTED_VALUE"""),7.410851411E9) -> 7410851411 | E18: =IFERROR(__xludf.DUMMYFUNCTION("""COMPUTED_VALUE"""),"Software Engineer") -> Software Engineer | F18: =IFERROR(__xludf.DUMMYFUNCTION("""COMPUTED_VALUE"""),"Backend") -> Backend | G18: =IFERROR(__xludf.DUMMYFUNCTION("""COMPUTED_VALUE"""),"singhrathoremohit@gmail.com") -> singhrathoremohit@gmail.com | H18: =IFERROR(__xludf.DUMMYFUNCTION("""COMPUTED_VALUE"""),"Piyush Shukla") -> Piyush Shukla | I18: =IFERROR(__xludf.DUMMYFUNCTION("""COMPUTED_VALUE"""),45222.0) -> 45222 | J18: =IFERROR(__xludf.DUMMYFUNCTION("""COMPUTED_VALUE"""),"Nidhi Khedekar") -> Nidhi Khedekar | K18: =IFERROR(__xludf.DUMMYFUNCTION("""COMPUTED_VALUE"""),"Joined") -> Joined | L18: =IFERROR(__xludf.DUMMYFUNCTION("""COMPUTED_VALUE"""),"In Office") -> In Office | M18: =IFERROR(__xludf.DUMMYFUNCTION("""COMPUTED_VALUE"""),"mohit.rathore@zupee.in") -> mohit.rathore@zupee.in | N18: =IFERROR(__xludf.DUMMYFUNCTION("""COMPUTED_VALUE"""),"D44FP97T0W") -> D44FP97T0W
A19: =IFERROR(__xludf.DUMMYFUNCTION("""COMPUTED_VALUE"""),45246.0) -> 45246 | B19: =IFERROR(__xludf.DUMMYFUNCTION("""COMPUTED_VALUE"""),"Shrasti Tomar") -> Shrasti Tomar | C19: =IFERROR(__xludf.DUMMYFUNCTION("""COMPUTED_VALUE"""),"Technology") -> Technology | D19: =IFERROR(__xludf.DUMMYFUNCTION("""COMPUTED_VALUE"""),9.71171279E9) -> 9711712790 | E19: =IFERROR(__xludf.DUMMYFUNCTION("""COMPUTED_VALUE"""),"Data Engineer") -> Data Engineer | F19: =IFERROR(__xludf.DUMMYFUNCTION("""COMPUTED_VALUE"""),"Data Engineering") -> Data Engineering | G19: =IFERROR(__xludf.DUMMYFUNCTION("""COMPUTED_VALUE"""),"shrastitomar123@gmail.com") -> shrastitomar123@gmail.com | H19: =IFERROR(__xludf.DUMMYFUNCTION("""COMPUTED_VALUE"""),"Aman Bahl") -> Aman Bahl | I19: =IFERROR(__xludf.DUMMYFUNCTION("""COMPUTED_VALUE"""),45229.0) -> 45229 | J19: =IFERROR(__xludf.DUMMYFUNCTION("""COMPUTED_VALUE"""),"Nidhi Khedekar") -> Nidhi Khedekar | K19: =IFERROR(__xludf.DUMMYFUNCTION("""COMPUTED_VALUE"""),"Joined") -> Joined | L19: =IFERROR(__xludf.DUMMYFUNCTION("""COMPUTED_VALUE"""),"In Office") -> In Office | M19: =IFERROR(__xludf.DUMMYFUNCTION("""COMPUTED_VALUE"""),"shrasti.tomar@zupee.in") -> shrasti.tomar@zupee.in | N19: =IFERROR(__xludf.DUMMYFUNCTION("""COMPUTED_VALUE"""),"M99FNLWVCF") -> M99FNLWVCF
A20: =IFERROR(__xludf.DUMMYFUNCTION("""COMPUTED_VALUE"""),45316.0) -> 45316 | B20: =IFERROR(__xludf.DUMMYFUNCTION("""COMPUTED_VALUE"""),"Sumit Chugh") -> Sumit Chugh | C20: =IFERROR(__xludf.DUMMYFUNCTION("""COMPUTED_VALUE"""),"Finance") -> Finance | D20: =IFERROR(__xludf.DUMMYFUNCTION("""COMPUTED_VALUE"""),9.811538749E9) -> 9811538749 | E20: =IFERROR(__xludf.DUMMYFUNCTION("""COMPUTED_VALUE"""),"Head of Finance") -> Head of Finance | F20: =IFERROR(__xludf.DUMMYFUNCTION("""COMPUTED_VALUE"""),"Finance") -> Finance | G20: =IFERROR(__xludf.DUMMYFUNCTION("""COMPUTED_VALUE"""),"sumitchugh81@gmail.com") -> sumitchugh81@gmail.com | H20: =IFERROR(__xludf.DUMMYFUNCTION("""COMPUTED_VALUE"""),"Dilsher Malhi") -> Dilsher Malhi | I20: =IFERROR(__xludf.DUMMYFUNCTION("""COMPUTED_VALUE"""),45224.0) -> 45224 | J20: =IFERROR(__xludf.DUMMYFUNCTION("""COMPUTED_VALUE"""),"M Sangeetha") -> M Sangeetha | K20: =IFERROR(__xludf.DUMMYFUNCTION("""COMPUTED_VALUE"""),"Joined") -> Joined | L20: =IFERROR(__xludf.DUMMYFUNCTION("""COMPUTED_VALUE"""),"In Office") -> In Office
A21: =IFERROR(__xludf.DUMMYFUNCTION("""COMPUTED_VALUE"""),45252.0) -> 45252 | B21: =IFERROR(__xludf.DUMMYFUNCTION("""COMPUTED_VALUE"""),"Kumar Shivam") -> Kumar Shivam | C21: =IFERROR(__xludf.DUMMYFUNCTION("""COMPUTED_VALUE"""),"Analytics") -> Analytics | D21: =IFERROR(__xludf.DUMMYFUNCTION("""COMPUTED_VALUE"""),9.471621193E9) -> 9471621193 | E21: =IFERROR(__xludf.DUMMYFUNCTION("""COMPUTED_VALUE"""),"Data Analyst") -> Data Analyst | F21: =IFERROR(__xludf.DUMMYFUNCTION("""COMPUTED_VALUE"""),"Product Analytics") -> Product Analytics | G21: =IFERROR(__xludf.DUMMYFUNCTION("""COMPUTED_VALUE"""),"kumarshivamdsdl@gmail.com") -> kumarshivamdsdl@gmail.com | H21: =IFERROR(__xludf.DUMMYFUNCTION("""COMPUTED_VALUE"""),"Shwetank Anand") -> Shwetank Anand | I21: =IFERROR(__xludf.DUMMYFUNCTION("""COMPUTED_VALUE"""),45222.0) -> 45222 | J21: =IFERROR(__xludf.DUMMYFUNCTION("""COMPUTED_VALUE"""),"Mamta Pandey") -> Mamta Pandey | K21: =IFERROR(__xludf.DUMMYFUNCTION("""COMPUTED_VALUE"""),"Offer Declined") -> Offer Declined | L21: =IFERROR(__xludf.DUMMYFUNCTION("""COMPUTED_VALUE"""),"In Office") -> In Office
A22: =IFERROR(__xludf.DUMMYFUNCTION("""COMPUTED_VALUE"""),45272.0) -> 45272 | B22: =IFERROR(__xludf.DUMMYFUNCTION("""COMPUTED_VALUE"""),"Rajkumar Singh") -> Rajkumar Singh | C22: =IFERROR(__xludf.DUMMYFUNCTION("""COMPUTED_VALUE"""),"Corporate") -> Corporate | D22: =IFERROR(__xludf.DUMMYFUNCTION("""COMPUTED_VALUE"""),8.285299131E9) -> 8285299131 | E22: =IFERROR(__xludf.DUMMYFUNCTION("""COMPUTED_VALUE"""),"Manager- IT Administration") -> Manager- IT Administration | F22: =IFERROR(__xludf.DUMMYFUNCTION("""COMPUTED_VALUE"""),"Administration") -> Administration | G22: =IFERROR(__xludf.DUMMYFUNCTION("""COMPUTED_VALUE"""),"rajdainy@gmail.com") -> rajdainy@gmail.com | H22: =IFERROR(__xludf.DUMMYFUNCTION("""COMPUTED_VALUE"""),"Gaurav Sharma") -> Gaurav Sharma | I22: =IFERROR(__xludf.DUMMYFUNCTION("""COMPUTED_VALUE"""),45210.0) -> 45210 | J22: =IFERROR(__xludf.DUMMYFUNCTION("""COMPUTED_VALUE"""),"Mamta Pandey") -> Mamta Pandey | K22: =IFERROR(__xludf.DUMMYFUNCTION("""COMPUTED_VALUE"""),"Joined") -> Joined | L22: =IFERROR(__xludf.DUMMYFUNCTION("""COMPUTED_VALUE"""),"In Office") -> In Office | M22: =IFERROR(__xludf.DUMMYFUNCTION("""COMPUTED_VALUE"""),"rajkumar.singh@zupee.in") -> rajkumar.singh@zupee.in | N22: =IFERROR(__xludf.DUMMYFUNCTION("""COMPUTED_VALUE"""),"DPMV3N3") -> DPMV3N3
A23: =IFERROR(__xludf.DUMMYFUNCTION("""COMPUTED_VALUE"""),45253.0) -> 45253 | B23: =IFERROR(__xludf.DUMMYFUNCTION("""COMPUTED_VALUE"""),"Prateek Jain") -> Prateek Jain | C23: =IFERROR(__xludf.DUMMYFUNCTION("""COMPUTED_VALUE"""),"Technology") -> Technology | D23: =IFERROR(__xludf.DUMMYFUNCTION("""COMPUTED_VALUE"""),9.910763107E9) -> 9910763107 | E23: =IFERROR(__xludf.DUMMYFUNCTION("""COMPUTED_VALUE"""),"Staff Engineer") -> Staff Engineer | F23: =IFERROR(__xludf.DUMMYFUNCTION("""COMPUTED_VALUE"""),"Engineering") -> Engineering | G23: =IFERROR(__xludf.DUMMYFUNCTION("""COMPUTED_VALUE"""),"prateekj201@gmail.com") -> prateekj201@gmail.com | H23: =IFERROR(__xludf.DUMMYFUNCTION("""COMPUTED_VALUE"""),"Saurav Yadav") -> Saurav Yadav | I23: =IFERROR(__xludf.DUMMYFUNCTION("""COMPUTED_VALUE"""),45240.0) -> 45240 | J23: =IFERROR(__xludf.DUMMYFUNCTION("""COMPUTED_VALUE"""),"Rajneesh Yadav") -> Rajneesh Yadav | K23: =IFERROR(__xludf.DUMMYFUNCTION("""COMPUTED_VALUE"""),"Joined") -> Joined | L23: =IFERROR(__xludf.DUMMYFUNCTION("""COMPUTED_VALUE"""),"In Office") -> In Office | M23: =IFERROR(__xludf.DUMMYFUNCTION("""COMPUTED_VALUE"""),"prateek.jain@zupee.in") -> prateek.jain@zupee.in
A24: =IFERROR(__xludf.DUMMYFUNCTION("""COMPUTED_VALUE"""),45258.0) -> 45258 | B24: =IFERROR(__xludf.DUMMYFUNCTION("""COMPUTED_VALUE"""),"Satyam Jaiswal") -> Satyam Jaiswal | C24: =IFERROR(__xludf.DUMMYFUNCTION("""COMPUTED_VALUE"""),"Technology") -> Technology | D24: =IFERROR(__xludf.DUMMYFUNCTION("""COMPUTED_VALUE"""),7.318358838E9) -> 7318358838 | E24: =IFERROR(__xludf.DUMMYFUNCTION("""COMPUTED_VALUE"""),"Quality Assurance Engineer- 1") -> Quality Assurance Engineer- 1 | F24: =IFERROR(__xludf.DUMMYFUNCTION("""COMPUTED_VALUE"""),"Quality") -> Quality | G24: =IFERROR(__xludf.DUMMYFUNCTION("""COMPUTED_VALUE"""),"satyamjaiswal8828@gmail.com") -> satyamjaiswal8828@gmail.com | H24: =IFERROR(__xludf.DUMMYFUNCTION("""COMPUTED_VALUE"""),"Sahil Puri") -> Sahil Puri | I24: =IFERROR(__xludf.DUMMYFUNCTION("""COMPUTED_VALUE"""),45251.0) -> 45251 | J24: =IFERROR(__xludf.DUMMYFUNCTION("""COMPUTED_VALUE"""),"Mamta Pandey") -> Mamta Pandey | K24: =IFERROR(__xludf.DUMMYFUNCTION("""COMPUTED_VALUE"""),"Joined") -> Joined | L24: =IFERROR(__xludf.DUMMYFUNCTION("""COMPUTED_VALUE"""),"In Office") -> In Office | M24: =IFERROR(__xludf.DUMMYFUNCTION("""COMPUTED_VALUE"""),"satyam.jaiswal@zupee.in") -> satyam.jaiswal@zupee.in | N24: =IFERROR(__xludf.DUMMYFUNCTION("""COMPUTED_VALUE"""),"KD4V9Y5L9R") -> KD4V9Y5L9R
A25: =IFERROR(__xludf.DUMMYFUNCTION("""COMPUTED_VALUE"""),45261.0) -> 45261 | B25: =IFERROR(__xludf.DUMMYFUNCTION("""COMPUTED_VALUE"""),"Tushar Rajendra Patil") -> Tushar Rajendra Patil | C25: =IFERROR(__xludf.DUMMYFUNCTION("""COMPUTED_VALUE"""),"Technology") -> Technology | E25: =IFERROR(__xludf.DUMMYFUNCTION("""COMPUTED_VALUE"""),"Machine Learning Engineer") -> Machine Learning Engineer | F25: =IFERROR(__xludf.DUMMYFUNCTION("""COMPUTED_VALUE"""),"Data Science") -> Data Science | G25: =IFERROR(__xludf.DUMMYFUNCTION("""COMPUTED_VALUE"""),"tusharpatil487@gmail.com") -> tusharpatil487@gmail.com | H25: =IFERROR(__xludf.DUMMYFUNCTION("""COMPUTED_VALUE"""),"Sairam Mushyam") -> Sairam Mushyam | I25: =IFERROR(__xludf.DUMMYFUNCTION("""COMPUTED_VALUE"""),45204.0) -> 45204 | J25: =IFERROR(__xludf.DUMMYFUNCTION("""COMPUTED_VALUE"""),"Mamta Pandey") -> Mamta Pandey | K25: =IFERROR(__xludf.DUMMYFUNCTION("""COMPUTED_VALUE"""),"Joined") -> Joined | L25: =IFERROR(__xludf.DUMMYFUNCTION("""COMPUTED_VALUE"""),"In Office") -> In Office | M25: =IFERROR(__xludf.DUMMYFUNCTION("""COMPUTED_VALUE"""),"tushar.patil@zupee.in") -> tushar.patil@zupee.in | N25: =IFERROR(__xludf.DUMMYFUNCTION("""COMPUTED_VALUE"""),"JLQMHQ2K3P") -> JLQMHQ2K3P
A26: =IFERROR(__xludf.DUMMYFUNCTION("""COMPUTED_VALUE"""),45264.0) -> 45264 | B26: =IFERROR(__xludf.DUMMYFUNCTION("""COMPUTED_VALUE""")," Mukul Bhatt") -> Mukul Bhatt | C26: =IFERROR(__xludf.DUMMYFUNCTION("""COMPUTED_VALUE"""),"Technology") -> Technology | D26: =IFERROR(__xludf.DUMMYFUNCTION("""COMPUTED_VALUE"""),9.971757357E9) -> 9971757357 | E26: =IFERROR(__xludf.DUMMYFUNCTION("""COMPUTED_VALUE"""),"Quality Assurance Engineer- 1") -> Quality Assurance Engineer- 1 | F26: =IFERROR(__xludf.DUMMYFUNCTION("""COMPUTED_VALUE"""),"Quality") -> Quality | G26: =IFERROR(__xludf.DUMMYFUNCTION("""COMPUTED_VALUE"""),"mukulbhatt9@gmail.com") -> mukulbhatt9@gmail.com | H26: =IFERROR(__xludf.DUMMYFUNCTION("""COMPUTED_VALUE"""),"Sahil Puri") -> Sahil Puri | I26: =IFERROR(__xludf.DUMMYFUNCTION("""COMPUTED_VALUE"""),45261.0) -> 45261 | J26: =IFERROR(__xludf.DUMMYFUNCTION("""COMPUTED_VALUE"""),"Mamta Pandey") -> Mamta Pandey | K26: =IFERROR(__xludf.DUMMYFUNCTION("""COMPUTED_VALUE"""),"Joined") -> Joined | L26: =IFERROR(__xludf.DUMMYFUNCTION("""COMPUTED_VALUE"""),"In Office") -> In Office
A27: =IFERROR(__xludf.DUMMYFUNCTION("""COMPUTED_VALUE"""),45273.0) -> 45273 | B27: =IFERROR(__xludf.DUMMYFUNCTION("""COMPUTED_VALUE"""),"Adhip kushwaha") -> Adhip kushwaha | C27: =IFERROR(__xludf.DUMMYFUNCTION("""COMPUTED_VALUE"""),"Technology") -> Technology | D27: =IFERROR(__xludf.DUMMYFUNCTION("""COMPUTED_VALUE"""),9.899277132E9) -> 9899277132 | E27: =IFERROR(__xludf.DUMMYFUNCTION("""COMPUTED_VALUE"""),"Software Engineer- Android") -> Software Engineer- Android | F27: =IFERROR(__xludf.DUMMYFUNCTION("""COMPUTED_VALUE"""),"Product Analytics") -> Product Analytics | G27: =IFERROR(__xludf.DUMMYFUNCTION("""COMPUTED_VALUE"""),"adhipkushwaha@gmail.com") -> adhipkushwaha@gmail.com | H27: =IFERROR(__xludf.DUMMYFUNCTION("""COMPUTED_VALUE"""),"Anshul Mittal") -> Anshul Mittal | I27: =IFERROR(__xludf.DUMMYFUNCTION("""COMPUTED_VALUE"""),45272.0) -> 45272 | J27: =IFERROR(__xludf.DUMMYFUNCTION("""COMPUTED_VALUE"""),"Naina") -> Naina | K27: =IFERROR(__xludf.DUMMYFUNCTION("""COMPUTED_VALUE"""),"Joined") -> Joined | L27: =IFERROR(__xludf.DUMMYFUNCTION("""COMPUTED_VALUE"""),"In Office") -> In Office | M27: =IFERROR(__xludf.DUMMYFUNCTION("""COMPUTED_VALUE"""),"adhip.kushwaha@zupee.in") -> adhip.kushwaha@zupee.in | N27: =IFERROR(__xludf.DUMMYFUNCTION("""COMPUTED_VALUE"""),"W1JLFTH56T") -> W1JLFTH56T
A28: =IFERROR(__xludf.DUMMYFUNCTION("""COMPUTED_VALUE"""),45275.0) -> 45275 | B28: =IFERROR(__xludf.DUMMYFUNCTION("""COMPUTED_VALUE"""),"Sucheta Sharma") -> Sucheta Sharma | C28: =IFERROR(__xludf.DUMMYFUNCTION("""COMPUTED_VALUE"""),"Finance") -> Finance | D28: =IFERROR(__xludf.DUMMYFUNCTION("""COMPUTED_VALUE"""),7.89896444E9) -> 7898964440 | E28: =IFERROR(__xludf.DUMMYFUNCTION("""COMPUTED_VALUE"""),"Manager- Finance") -> Manager- Finance | F28: =IFERROR(__xludf.DUMMYFUNCTION("""COMPUTED_VALUE"""),"Finance") -> Finance | G28: =IFERROR(__xludf.DUMMYFUNCTION("""COMPUTED_VALUE"""),"sssuchetasharma@gmail.com") -> sssuchetasharma@gmail.com | H28: =IFERROR(__xludf.DUMMYFUNCTION("""COMPUTED_VALUE"""),"Hitesh Vats") -> Hitesh Vats | I28: =IFERROR(__xludf.DUMMYFUNCTION("""COMPUTED_VALUE"""),45247.0) -> 45247 | J28: =IFERROR(__xludf.DUMMYFUNCTION("""COMPUTED_VALUE"""),"Nidhi Khedekar") -> Nidhi Khedekar | K28: =IFERROR(__xludf.DUMMYFUNCTION("""COMPUTED_VALUE"""),"Joined") -> Joined | L28: =IFERROR(__xludf.DUMMYFUNCTION("""COMPUTED_VALUE"""),"In Office") -> In Office | M28: =IFERROR(__xludf.DUMMYFUNCTION("""COMPUTED_VALUE"""),"sucheta.sharma@zupee.in") -> sucheta.sharma@zupee.in
A29: =IFERROR(__xludf.DUMMYFUNCTION("""COMPUTED_VALUE"""),44944.0) -> 44944 | B29: =IFERROR(__xludf.DUMMYFUNCTION("""COMPUTED_VALUE"""),"Mohit Choudhary") -> Mohit Choudhary | C29: =IFERROR(__xludf.DUMMYFUNCTION("""COMPUTED_VALUE"""),"Analytics") -> Analytics | D29: =IFERROR(__xludf.DUMMYFUNCTION("""COMPUTED_VALUE"""),8.561946709E9) -> 8561946709 | E29: =IFERROR(__xludf.DUMMYFUNCTION("""COMPUTED_VALUE"""),"Senior Data Analyst") -> Senior Data Analyst | F29: =IFERROR(__xludf.DUMMYFUNCTION("""COMPUTED_VALUE"""),"Product Analytics") -> Product Analytics | G29: =IFERROR(__xludf.DUMMYFUNCTION("""COMPUTED_VALUE"""),"choudharymohit1907@gmail.com") -> choudharymohit1907@gmail.com | H29: =IFERROR(__xludf.DUMMYFUNCTION("""COMPUTED_VALUE"""),"Shwetank Anand") -> Shwetank Anand | I29: =IFERROR(__xludf.DUMMYFUNCTION("""COMPUTED_VALUE"""),45251.0) -> 45251 | J29: =IFERROR(__xludf.DUMMYFUNCTION("""COMPUTED_VALUE"""),"Mamta Pandey") -> Mamta Pandey | K29: =IFERROR(__xludf.DUMMYFUNCTION("""COMPUTED_VALUE"""),"Joined") -> Joined | L29: =IFERROR(__xludf.DUMMYFUNCTION("""COMPUTED_VALUE"""),"In Office") -> In Office | M29: =IFERROR(__xludf.DUMMYFUNCTION("""COMPUTED_VALUE"""),"mohit.choudhary@zupee.in") -> mohit.choudhary@zupee.in
A30: =IFERROR(__xludf.DUMMYFUNCTION("""COMPUTED_VALUE"""),45397.0) -> 45397 | B30: =IFERROR(__xludf.DUMMYFUNCTION("""COMPUTED_VALUE"""),"Eeshma Anand") -> Eeshma Anand | C30: =IFERROR(__xludf.DUMMYFUNCTION("""COMPUTED_VALUE"""),"Product") -> Product | D30: =IFERROR(__xludf.DUMMYFUNCTION("""COMPUTED_VALUE"""),7.982263396E9) -> 7982263396 | E30: =IFERROR(__xludf.DUMMYFUNCTION("""COMPUTED_VALUE"""),"Product Manager") -> Product Manager | F30: =IFERROR(__xludf.DUMMYFUNCTION("""COMPUTED_VALUE"""),"Product") -> Product | G30: =IFERROR(__xludf.DUMMYFUNCTION("""COMPUTED_VALUE"""),"eeshma.anand@gmail.com") -> eeshma.anand@gmail.com | H30: =IFERROR(__xludf.DUMMYFUNCTION("""COMPUTED_VALUE"""),"Naveen Kadyan") -> Naveen Kadyan | I30: =IFERROR(__xludf.DUMMYFUNCTION("""COMPUTED_VALUE"""),45260.0) -> 45260 | J30: =IFERROR(__xludf.DUMMYFUNCTION("""COMPUTED_VALUE"""),"M Sangeetha") -> M Sangeetha | K30: =IFERROR(__xludf.DUMMYFUNCTION("""COMPUTED_VALUE"""),"Joined") -> Joined | L30: =IFERROR(__xludf.DUMMYFUNCTION("""COMPUTED_VALUE"""),"In Office") -> In Office | M30: =IFERROR(__xludf.DUMMYFUNCTION("""COMPUTED_VALUE"""),"eeshma.anand@zupee.in") -> eeshma.anand@zupee.in | N30: =IFERROR(__xludf.DUMMYFUNCTION("""COMPUTED_VALUE"""),"JY9YR6J6HV") -> JY9YR6J6HV
A31: =IFERROR(__xludf.DUMMYFUNCTION("""COMPUTED_VALUE"""),45266.0) -> 45266 | B31: =IFERROR(__xludf.DUMMYFUNCTION("""COMPUTED_VALUE"""),"Anjali") -> Anjali | C31: =IFERROR(__xludf.DUMMYFUNCTION("""COMPUTED_VALUE"""),"Customer Experience") -> Customer Experience | D31: =IFERROR(__xludf.DUMMYFUNCTION("""COMPUTED_VALUE"""),9.540863058E9) -> 9540863058 | E31: =IFERROR(__xludf.DUMMYFUNCTION("""COMPUTED_VALUE"""),"Quality Auditor- Executive") -> Quality Auditor- Executive | F31: =IFERROR(__xludf.DUMMYFUNCTION("""COMPUTED_VALUE"""),"Customer Relation Management") -> Customer Relation Management | G31: =IFERROR(__xludf.DUMMYFUNCTION("""COMPUTED_VALUE"""),"annirai345@gmail.com") -> annirai345@gmail.com | H31: =IFERROR(__xludf.DUMMYFUNCTION("""COMPUTED_VALUE"""),"Suvra Das") -> Suvra Das | I31: =IFERROR(__xludf.DUMMYFUNCTION("""COMPUTED_VALUE"""),45264.0) -> 45264 | J31: =IFERROR(__xludf.DUMMYFUNCTION("""COMPUTED_VALUE"""),"Nidhi Khedekar") -> Nidhi Khedekar | K31: =IFERROR(__xludf.DUMMYFUNCTION("""COMPUTED_VALUE"""),"Joined") -> Joined | L31: =IFERROR(__xludf.DUMMYFUNCTION("""COMPUTED_VALUE"""),"In Office") -> In Office | M31: =IFERROR(__xludf.DUMMYFUNCTION("""COMPUTED_VALUE"""),"anjali.pal@zupee.in") -> anjali.pal@zupee.in | N31: =IFERROR(__xludf.DUMMYFUNCTION("""COMPUTED_VALUE"""),"PW03VMFN") -> PW03VMFN
A32: =IFERROR(__xludf.DUMMYFUNCTION("""COMPUTED_VALUE"""),45271.0) -> 45271 | B32: =IFERROR(__xludf.DUMMYFUNCTION("""COMPUTED_VALUE"""),"Gaurav Khanna") -> Gaurav Khanna | C32: =IFERROR(__xludf.DUMMYFUNCTION("""COMPUTED_VALUE"""),"Admin") -> Admin | D32: =IFERROR(__xludf.DUMMYFUNCTION("""COMPUTED_VALUE"""),8.826268269E9) -> 8826268269 | E32: =IFERROR(__xludf.DUMMYFUNCTION("""COMPUTED_VALUE"""),"AM-Administration") -> AM-Administration | F32: =IFERROR(__xludf.DUMMYFUNCTION("""COMPUTED_VALUE"""),"Administration") -> Administration | G32: =IFERROR(__xludf.DUMMYFUNCTION("""COMPUTED_VALUE"""),"g29.khanna@yahoo.co.in") -> g29.khanna@yahoo.co.in | H32: =IFERROR(__xludf.DUMMYFUNCTION("""COMPUTED_VALUE"""),"Vijay Singh") -> Vijay Singh | I32: =IFERROR(__xludf.DUMMYFUNCTION("""COMPUTED_VALUE"""),45264.0) -> 45264 | J32: =IFERROR(__xludf.DUMMYFUNCTION("""COMPUTED_VALUE"""),"Nidhi Khedekar") -> Nidhi Khedekar | K32: =IFERROR(__xludf.DUMMYFUNCTION("""COMPUTED_VALUE"""),"Joined") -> Joined | L32: =IFERROR(__xludf.DUMMYFUNCTION("""COMPUTED_VALUE"""),"In Office") -> In Office | M32: =IFERROR(__xludf.DUMMYFUNCTION("""COMPUTED_VALUE"""),"gaurav.khanna@zupee.in") -> gaurav.khanna@zupee.in | N32: =IFERROR(__xludf.DUMMYFUNCTION("""COMPUTED_VALUE"""),"FW9FFY3") -> FW9FFY3
A33: =IFERROR(__xludf.DUMMYFUNCTION("""COMPUTED_VALUE"""),45271.0) -> 45271 | B33: =IFERROR(__xludf.DUMMYFUNCTION("""COMPUTED_VALUE"""),"Mohit Bakshi") -> Mohit Bakshi | C33: =IFERROR(__xludf.DUMMYFUNCTION("""COMPUTED_VALUE"""),"Technology") -> Technology | D33: =IFERROR(__xludf.DUMMYFUNCTION("""COMPUTED_VALUE"""),6.003534136E9) -> 6003534136 | E33: =IFERROR(__xludf.DUMMYFUNCTION("""COMPUTED_VALUE"""),"Software Engineer Trainee") -> Software Engineer Trainee | F33: =IFERROR(__xludf.DUMMYFUNCTION("""COMPUTED_VALUE"""),"Backend") -> Backend | G33: =IFERROR(__xludf.DUMMYFUNCTION("""COMPUTED_VALUE"""),"mohit19bakshi@gmail.com") -> mohit19bakshi@gmail.com | H33: =IFERROR(__xludf.DUMMYFUNCTION("""COMPUTED_VALUE"""),"Atique Firoz") -> Atique Firoz | I33: =IFERROR(__xludf.DUMMYFUNCTION("""COMPUTED_VALUE"""),45268.0) -> 45268 | J33: =IFERROR(__xludf.DUMMYFUNCTION("""COMPUTED_VALUE"""),"Nidhi Khedekar") -> Nidhi Khedekar | K33: =IFERROR(__xludf.DUMMYFUNCTION("""COMPUTED_VALUE"""),"Joined") -> Joined | L33: =IFERROR(__xludf.DUMMYFUNCTION("""COMPUTED_VALUE"""),"In Office") -> In Office | M33: =IFERROR(__xludf.DUMMYFUNCTION("""COMPUTED_VALUE"""),"mohit.bakshi@zupee.in") -> mohit.bakshi@zupee.in
A34: =IFERROR(__xludf.DUMMYFUNCTION("""COMPUTED_VALUE"""),45287.0) -> 45287 | B34: =IFERROR(__xludf.DUMMYFUNCTION("""COMPUTED_VALUE"""),"Mehul Deep") -> Mehul Deep | C34: =IFERROR(__xludf.DUMMYFUNCTION("""COMPUTED_VALUE"""),"Analytics") -> Analytics | D34: =IFERROR(__xludf.DUMMYFUNCTION("""COMPUTED_VALUE"""),8.527423606E9) -> 8527423606 | E34: =IFERROR(__xludf.DUMMYFUNCTION("""COMPUTED_VALUE"""),"Senior Data Analyst") -> Senior Data Analyst | F34: =IFERROR(__xludf.DUMMYFUNCTION("""COMPUTED_VALUE"""),"Product Analytics") -> Product Analytics | G34: =IFERROR(__xludf.DUMMYFUNCTION("""COMPUTED_VALUE"""),"mdmaurya25@gmail.com") -> mdmaurya25@gmail.com | H34: =IFERROR(__xludf.DUMMYFUNCTION("""COMPUTED_VALUE"""),"Shwetank Anand") -> Shwetank Anand | I34: =IFERROR(__xludf.DUMMYFUNCTION("""COMPUTED_VALUE"""),45268.0) -> 45268 | J34: =IFERROR(__xludf.DUMMYFUNCTION("""COMPUTED_VALUE"""),"Mamta Pandey") -> Mamta Pandey | K34: =IFERROR(__xludf.DUMMYFUNCTION("""COMPUTED_VALUE"""),"Offer Declined") -> Offer Declined | L34: =IFERROR(__xludf.DUMMYFUNCTION("""COMPUTED_VALUE"""),"In Office") -> In Office
